## 19.1 概述
1、`Throwable`类是所有错误（`error`类）和异常（`exception`类）的超类

2、异常：就是程序出现了不正常的情况

3、异常体系

<img src="https://img-blog.csdnimg.cn/20210314094454730.png?x-oss-process=image/watermark,type_ZmFuZ3poZW5naGVpdGk,shadow_10,text_aHR0cHM6Ly9ibG9nLmNzZG4ubmV0L3FxXzQ1NjUwODk5,size_16,color_FFFFFF,t_70" alt="在这里插入图片描述" style="zoom:50%;" />

<span style="background: yellow;">Error</span>：严重问题，不需要处理（<span style="background: yellow;">非检查型异常</span>）

<span style="background: yellow;">Exception</span>：异常类，表示程序本身可以处理的问题

- **RuntimeException**：编译期不检查，出现问题之后需要回来修改代码（<span style="background: yellow;">非检查型异常</span>）
包括：错误的强制类型转换、数组访问越界、访问null指针
- **非RuntimeException**：编译期必须处理，否则不能通过编译（<span style="background: yellow;">检查型异常</span>）
包括：试图超越文件末尾继续添加数据、试图打开一个不存在的文件、试图根据指定的字符串查找class对象，而这个类并不存在

## 19.2 JVM的默认处理方案
如果程序出现了问题，我们没有做任何处理，最终JVM会做默认的处理：
- 把异常的名称、原因、位置等信息输出在控制台
- 程序停止运行

## 19.3 异常处理
两种方案：
- 使用`try..catch..`
- 使用`throws`

### 19.3.1 捕获异常：try-catch
格式：

```java
try{
	可能出现的代码
}catch(异常类名 变量名){
	异常处理
}

执行流程：
1、程序从try里面的代码开始执行
2、出现异常，会自动生成一个异常类对象，该异常类对象将被提交给Java运行系统
3、当java运行时，吸引接收到异常对象，回到catch中去找匹配的异常对象，找到后进行异常的处理
4、执行完毕后，程序还可以继续往下执行
```
例子：

```java
try{
	int[] arr = {1,2,3};
	System.out.println(arr[3]);
}catch(ArrayIndexOutOfBoundsException e){
	e.printStackTrace();
}
```
### 19.3.2 Throwable成员方法
1、`public String getMessage()`：返回此throwable的详细消息字符串

2、`public String toString()`：返回此可抛出的简短描述

3、`public void printStackTrace()`：把异常的错误信息输出在控制台

#### getMessage()
源代码：
```java
public class Throwable{
	private String detailMessage;
	
	public Throwable(String message){
		detailMessage = message;
	}
    public String getMessage() {
        return detailMessage;
    }
}
```
例子：

```java
try{
    int[] arr = {1,2,3};
    System.out.println(arr[10]);
}catch(ArrayIndexOutOfBoundsException e){
    System.out.println(e.getMessage());
}
```

#### toString()

```java
try{
    int[] arr = {1,2,3};
    System.out.println(arr[10]);
}catch(ArrayIndexOutOfBoundsException e){
    System.out.println(e.toString());
}

输出：java.lang.ArrayIndexOutOfBoundsException: 10
```

#### printStackTrace()
```java
try{
	int[] arr = {1,2,3};
	System.out.println(arr[10]);
}catch(ArrayIndexOutOfBoundsException e){
	e.printStackTrace();
}
输出:
java.lang.ArrayIndexOutOfBoundsException: 10
	at Test.main(Test.java:13)
```

### 19.3.3 抛出异常：throws
格式：

```java
throws 异常类名
```
例子：

```java
//运行时异常
public void method()throws ArrayIndexOutOfBoundsException{
	int[] arr = {1,2,3};
	System.out.println(arr[3]);
}

//编译时异常
public void method2()thorws ParseException{
	String s = "2020-01-01";
	SimpleDateFormat sdf = new SimpleDateFormat("yyyy-MM-dd");
	Date d = sdf.parse(s);
	System.out.println(d);
}

main{
	method();//不能往下运行
	method2();//使用try-catch即可往下运行
}
```
注意：
- `编译时异常`必须要处理，有两种方案：try-catch或者throws，如果采用throws，将来谁调用谁处理
- `运行时异常`可以不处理，出现问题后需要修改代码

## 19.4 自定义异常
格式：

```java
public class 异常类名 extends Exception{
	无参构造
	带参构造
}
```
例子：

```java
public class scoreException extends Exception{
	public scoreException(){}
	
	public scoreException(String message){
		super(message);
	}
}

public class teacher{
	public void check(int score)throws scoreException{
		if(score<0||score>100){
			//抛出异常
			throw new scoreException("error");
		}else{
			System.out.println("normal");
		}
	}
}
```
### throws和throw的区别
1、throws：
- 用在方法声明后面，跟的是异常类名
- 表示抛出异常，由该方法的调用者处理
- 表示出现异常的一种可能性，并不一定会发生这些异常

2、throw：
- 用在方法体内，跟的是异常对象名
- 表示抛出异常，由方法体内的语句处理
- 执行throw一定抛出了某种异常

## 19.5 finally子句

> 代码抛出一个异常后，就会停止处理这个方法中剩余的代码，并退出这个方法；如果这个方法已经获取了一些本地资源，而且这些资源必须处理，这就会存在问题。

不管是否有异常被捕获，`finally`子句中的代码都会执行。

例子：

```java
var in = new FileInputStream(...);
try{
//1
导致异常的执行代码
//2
}catch(IOexception e){
//3
show error message
//4
}finally{
//5
in.close();
}
//6
```
有三种情况会执行finally子句：
1. 代码没有抛出异常，1、2、5、6
2. 代码抛出一个异常，并在`catch`中捕获。如果catch中没有抛出异常，程序将会执行`finally`子句之后的第一条语句（1、3、4、5、6）；如果抛出异常了，异常被抛回这个方法的调用者（1、3、5）
3. 代码抛出了一个异常，但没有`catch`子句捕获这个异常，（1、5）


在以下 3 种特殊情况下，`finally` 块不会被执行：

1. 在 `try` 或 `finally` 块中用了 `System.exit(int)`退出程序。但是，如果 `System.exit(int)` 在异常语句之后，`finally `还是会被执行
2. 程序所在的线程死亡。
3. 关闭 CPU。

注意： 当 `try `语句和 `finally` 语句中都有 `return` 语句时，在方法返回之前，`finally` 语句的内容将被执行，并且 `finally` 语句的返回值将会覆盖原始的返回值。

## 19.6 try-with-resources

格式：

```java
try(Resource res=...){
	work with res
}
```
`try`退出时，会自动调用`res.close()`

1、适用范围（资源的定义）： 任何实现 `java.lang.AutoCloseable`或者 `java.io.Closeable` 的对象，即==需要关闭资源==

> 面对必须要关闭的资源，我们总是应该优先使用 try-with-resources
> 而不是try-finally。随之产生的代码更简短，更清晰，产生的异常对我们也更有用。try-with-resources语句让我们更容易编写必须要关闭的资源的代码，若采用try-finally则几乎做不到这点。

Java 中类似于`InputStream`、`OutputStream` 、`Scanner` 、`PrintWriter`等的资源都需要我们调用`close()`方法来手动关闭，一般情况下我们都是通过`try-catch-finally`语句来实现这个需求，如下：

   

```java
 //读取文本文件的内容
    Scanner scanner = null;
    try {
        scanner = new Scanner(new File("D://read.txt"));
        while (scanner.hasNext()) {
            System.out.println(scanner.nextLine());
        }
    } catch (FileNotFoundException e) {
        e.printStackTrace();
    } finally {
        if (scanner != null) {
            scanner.close();
        }
    }
```

使用 Java 7 之后的 `try-with-resources` 语句改造上面的代码:

```java
try (Scanner scanner = new Scanner(new File("test.txt"))) {
    while (scanner.hasNext()) {
        System.out.println(scanner.nextLine());
    }
} catch (FileNotFoundException fnfe) {
    fnfe.printStackTrace();
}
```

当然多个资源需要关闭的时候，使用 `try-with-resources `实现起来也非常简单，如果你还是用`try-catch-finally`可能会带来很多问题。

通过使用分号分隔，可以在`try-with-resources`块中声明多个资源。

```java
try (
BufferedInputStream bin = new BufferedInputStream(new FileInputStream(new File("test.txt")));
BufferedOutputStream bout = new BufferedOutputStream(new FileOutputStream(new File("out.txt")))) 
{
            int b;
            while ((b = bin.read()) != -1) {
                bout.write(b);
            }
        }
        catch (IOException e) {
            e.printStackTrace();
        }
```

> try-with-resource语句自身也可以有catch，甚至可以有finally，这些子句会在关闭资源之后执行
